[2023-10-13T01:04:51.215+0000] {taskinstance.py:1157} INFO - Dependencies all met for dep_context=non-requeueable deps ti=<TaskInstance: our_first_dag_w_python_v4.salutation scheduled__2023-09-30T00:00:00+00:00 [queued]>
[2023-10-13T01:04:51.300+0000] {taskinstance.py:1157} INFO - Dependencies all met for dep_context=requeueable deps ti=<TaskInstance: our_first_dag_w_python_v4.salutation scheduled__2023-09-30T00:00:00+00:00 [queued]>
[2023-10-13T01:04:51.302+0000] {taskinstance.py:1359} INFO - Starting attempt 1 of 6
[2023-10-13T01:04:51.359+0000] {taskinstance.py:1380} INFO - Executing <Task(PythonOperator): salutation> on 2023-09-30 00:00:00+00:00
[2023-10-13T01:04:51.370+0000] {standard_task_runner.py:57} INFO - Started process 575 to run task
[2023-10-13T01:04:51.390+0000] {standard_task_runner.py:84} INFO - Running: ['***', 'tasks', 'run', 'our_first_dag_w_python_v4', 'salutation', 'scheduled__2023-09-30T00:00:00+00:00', '--job-id', '677', '--raw', '--subdir', 'DAGS_FOLDER/create_dag_with_pythonoperator.py', '--cfg-path', '/tmp/tmpi5dux9ks']
[2023-10-13T01:04:51.417+0000] {standard_task_runner.py:85} INFO - Job 677: Subtask salutation
[2023-10-13T01:04:51.678+0000] {task_command.py:415} INFO - Running <TaskInstance: our_first_dag_w_python_v4.salutation scheduled__2023-09-30T00:00:00+00:00 [running]> on host 1a5849cd9120
[2023-10-13T01:04:51.809+0000] {taskinstance.py:1660} INFO - Exporting env vars: AIRFLOW_CTX_DAG_OWNER='varun' AIRFLOW_CTX_DAG_ID='our_first_dag_w_python_v4' AIRFLOW_CTX_TASK_ID='salutation' AIRFLOW_CTX_EXECUTION_DATE='2023-09-30T00:00:00+00:00' AIRFLOW_CTX_TRY_NUMBER='1' AIRFLOW_CTX_DAG_RUN_ID='scheduled__2023-09-30T00:00:00+00:00'
[2023-10-13T01:04:51.812+0000] {taskinstance.py:1935} ERROR - Task failed with exception
Traceback (most recent call last):
  File "/home/airflow/.local/lib/python3.8/site-packages/airflow/operators/python.py", line 192, in execute
    return_value = self.execute_callable()
  File "/home/airflow/.local/lib/python3.8/site-packages/airflow/operators/python.py", line 209, in execute_callable
    return self.python_callable(*self.op_args, **self.op_kwargs)
  File "/opt/airflow/dags/create_dag_with_pythonoperator.py", line 12, in greet
    name=ti.xcoms_pull(task_ids='get_name')
AttributeError: 'TaskInstance' object has no attribute 'xcoms_pull'
[2023-10-13T01:04:51.849+0000] {taskinstance.py:1398} INFO - Marking task as UP_FOR_RETRY. dag_id=our_first_dag_w_python_v4, task_id=salutation, execution_date=20230930T000000, start_date=20231013T010451, end_date=20231013T010451
[2023-10-13T01:04:51.884+0000] {standard_task_runner.py:104} ERROR - Failed to execute job 677 for task salutation ('TaskInstance' object has no attribute 'xcoms_pull'; 575)
[2023-10-13T01:04:51.943+0000] {local_task_job_runner.py:228} INFO - Task exited with return code 1
[2023-10-13T01:04:51.979+0000] {taskinstance.py:2776} INFO - 0 downstream tasks scheduled from follow-on schedule check
